<?xml version="1.0" encoding="utf-8"?>
<!-- =================================================================================== -->
<!-- |    This document was autogenerated by xacro from car.xacro                      | -->
<!-- |    EDITING THIS FILE BY HAND IS NOT RECOMMENDED                                 | -->
<!-- =================================================================================== -->
<robot name="car">
  <!-- inertial parameter macros -->
  <!-- geometry macros -->
  <!-- transmission macros -->
  <!-- Size of square 'camera' box -->
  <!-- Add chassis and it's inertia link -->
  <link name="base_link">
  </link>
  <link name="chassis">
    <visual>
      <origin rpy="0 0 0" xyz="0 0 0"/>
      <geometry>
        <mesh filename="package://car_description/meshes/chassis.STL"/>
      </geometry>
      <material name="blue"/>
    </visual>
  </link>
  <joint name="base_link_joint" type="fixed">
    <origin rpy="0 0 0" xyz="0 0 0.05"/>
    <parent link="base_link"/>
    <child link="chassis"/>
  </joint>
  <link name="chassis_inertia">
    <inertial>
      <origin rpy="0 0 0" xyz="0.1477 0 0"/>
      <mass value="4.0"/>
      <inertia ixx="0.010609" ixy="0" ixz="0" iyy="0.050409" iyz="0" izz="0.05865"/>
    </inertial>
  </link>
  <joint name="chassis_inertia_joint" type="fixed">
    <origin rpy="0 0 0" xyz="0 0 0"/>
    <parent link="chassis"/>
    <child link="chassis_inertia"/>
  </joint>
  <!-- Add the left rear wheel with its joints and tranmissions -->
  <link name="left_rear_wheel">
    <inertial>
      <origin rpy="0 0 0" xyz="0 0 -0.0225"/>
      <mass value="0.34055"/>
      <inertia ixx="0.00026046" ixy="0" ixz="0" iyy="0.00026046" iyz="0" izz="0.00041226"/>
    </inertial>
    <visual>
      <origin rpy="0 0 0" xyz="0 0 0"/>
      <geometry>
        <mesh filename="package://car_description/meshes/left_rear_wheel.STL"/>
      </geometry>
      <material name="black"/>
    </visual>
    <collision>
      
      <origin rpy="0 0 0" xyz="0 0 -0.0225"/>
      <geometry>
        <cylinder length="0.045" radius="0.05"/>
      </geometry>
    </collision>
  </link>
  <joint name="left_rear_wheel_joint" type="continuous">
    <origin rpy="1.5708 0 0" xyz="0 0.1 0"/>
    <parent link="chassis"/>
    <child link="left_rear_wheel"/>
    <axis xyz="0 0 -1"/>
    <limit effort="10" velocity="100"/>
  </joint>
  <transmission name="left_rear_wheel_transmission" type="SimpleTransmission">
    <type>transmission_interface/SimpleTransmission</type>
    <joint name="left_rear_wheel_joint">
      <hardwareInterface>EffortJointInterface</hardwareInterface>
    </joint>
    <actuator name="left_rear_wheel_motor">
      <hardwareInterface>EffortJointInterface</hardwareInterface>
      <mechanicalReduction>1</mechanicalReduction>
    </actuator>
  </transmission>
  <!-- Add the right rear wheel with its joints and tranmissions -->
  <link name="right_rear_wheel">
    <inertial>
      <origin rpy="0 0 0" xyz="0 0 0.0225"/>
      <mass value="0.34055"/>
      <inertia ixx="0.00026046" ixy="0" ixz="0" iyy="0.00026046" iyz="0" izz="0.00041226"/>
    </inertial>
    <visual>
      <origin rpy="0 0 0" xyz="0 0 0"/>
      <geometry>
        <mesh filename="package://car_description/meshes/right_rear_wheel.STL"/>
      </geometry>
      <material name="black"/>
    </visual>
    <collision>
      <origin rpy="0 0 0" xyz="0 0 0.0225"/>
      <geometry>
        <cylinder length="0.045" radius="0.05"/>
      </geometry>
    </collision>
  </link>
  <joint name="right_rear_wheel_joint" type="continuous">
    <origin rpy="1.5708 0 0" xyz="0 -0.1 0"/>
    <parent link="chassis"/>
    <child link="right_rear_wheel"/>
    <axis xyz="0 0 -1"/>
    <limit effort="10" velocity="100"/>
  </joint>
  <transmission name="right_rear_wheel_transmission" type="SimpleTransmission">
    <type>transmission_interface/SimpleTransmission</type>
    <joint name="right_rear_wheel_joint">
      <hardwareInterface>EffortJointInterface</hardwareInterface>
    </joint>
    <actuator name="right_rear_wheel_motor">
      <hardwareInterface>EffortJointInterface</hardwareInterface>
      <mechanicalReduction>1</mechanicalReduction>
    </actuator>
  </transmission>
  <!-- Add the left steering hinge with its joints and tranmissions -->
  <link name="left_steering_hinge">
    <inertial>
      <origin rpy="0 0 0" xyz="0 0 0"/>
      <mass value="0.100"/>
      <inertia ixx="4E-06" ixy="0" ixz="0" iyy="4E-06" iyz="0" izz="4E-06"/>
    </inertial>
    <visual>
      <origin rpy="0 0 0" xyz="0 0 0"/>
      <geometry>
        <mesh filename="package://car_description/meshes/left_steering_hinge.STL"/>
      </geometry>
      <material name="grey"/>
    </visual>
  </link>
  <joint name="left_steering_hinge_joint" type="revolute">
    <origin rpy="0 1.5708 0" xyz="0.325 0.1 0"/>
    <parent link="chassis"/>
    <child link="left_steering_hinge"/>
    <axis xyz="-1 0 0"/>
    <limit effort="10" lower="-1.0" upper="1.0" velocity="100"/>
  </joint>
  <transmission name="left_steering_hinge_transmission" type="SimpleTransmission">
    <type>transmission_interface/SimpleTransmission</type>
    <joint name="left_steering_hinge_joint">
      <hardwareInterface>EffortJointInterface</hardwareInterface>
    </joint>
    <actuator name="left_steering_hinge_motor">
      <hardwareInterface>EffortJointInterface</hardwareInterface>
      <mechanicalReduction>1</mechanicalReduction>
    </actuator>
  </transmission>
  <!-- Add the right steering hinge with its joints and tranmissions -->
  <link name="right_steering_hinge">
    <inertial>
      <origin rpy="0 0 0" xyz="0 0 0"/>
      <mass value="0.100"/>
      <inertia ixx="4E-06" ixy="0" ixz="0" iyy="4E-06" iyz="0" izz="4E-06"/>
    </inertial>
    <visual>
      <origin rpy="0 0 0" xyz="0 0 0"/>
      <geometry>
        <mesh filename="package://car_description/meshes/right_steering_hinge.STL"/>
      </geometry>
      <material name="grey"/>
    </visual>
  </link>
  <joint name="right_steering_hinge_joint" type="continuous">
    <origin rpy="0 1.5708 0" xyz="0.325 -0.1 0"/>
    <parent link="chassis"/>
    <child link="right_steering_hinge"/>
    <axis xyz="-1 0 0"/>
    <limit effort="10" lower="-1.0" upper="1.0" velocity="100"/>
  </joint>
  <transmission name="right_steering_hinge_transmission" type="SimpleTransmission">
    <type>transmission_interface/SimpleTransmission</type>
    <joint name="right_steering_hinge_joint">
      <hardwareInterface>EffortJointInterface</hardwareInterface>
    </joint>
    <actuator name="right_steering_hinge_motor">
      <hardwareInterface>EffortJointInterface</hardwareInterface>
      <mechanicalReduction>1</mechanicalReduction>
    </actuator>
  </transmission>
  <!-- Add the left front wheel with its joints and tranmissions -->
  <link name="left_front_wheel">
    <inertial>
      <origin rpy="0 0 0" xyz="0 0 -0.0225"/>
      <mass value="0.34055"/>
      <inertia ixx="0.00026046" ixy="0" ixz="0" iyy="0.00026046" iyz="0" izz="0.00041226"/>
    </inertial>
    <visual>
      <origin rpy="0 0 0" xyz="0 0 0"/>
      <geometry>
        <mesh filename="package://car_description/meshes/left_front_wheel.STL"/>
      </geometry>
      <material name="black"/>
    </visual>
    <collision>
      <origin rpy="0 0 0" xyz="0 0 -0.0225"/>
      <geometry>
        <cylinder length="0.045" radius="0.05"/>
      </geometry>
    </collision>
  </link>
  <joint name="left_front_wheel_joint" type="continuous">
    <origin rpy="1.5708 0 0" xyz="0 0 0"/>
    <parent link="left_steering_hinge"/>
    <child link="left_front_wheel"/>
    <axis xyz="0 0 -1"/>
    <limit effort="10" velocity="100"/>
  </joint>
  <transmission name="left_front_wheel_transmission" type="SimpleTransmission">
    <type>transmission_interface/SimpleTransmission</type>
    <joint name="left_front_wheel_joint">
      <hardwareInterface>EffortJointInterface</hardwareInterface>
    </joint>
    <actuator name="left_front_wheel_motor">
      <hardwareInterface>EffortJointInterface</hardwareInterface>
      <mechanicalReduction>1</mechanicalReduction>
    </actuator>
  </transmission>
  <!-- Add the left front wheel with its joints and tranmissions -->
  <link name="right_front_wheel">
    <inertial>
      <origin rpy="0 0 0" xyz="0 0 0.0225"/>
      <mass value="0.34055"/>
      <inertia ixx="0.00026046" ixy="0" ixz="0" iyy="0.00026046" iyz="0" izz="0.00041226"/>
    </inertial>
    <visual>
      <origin rpy="0 0 0" xyz="0 0 0"/>
      <geometry>
        <mesh filename="package://car_description/meshes/right_front_wheel.STL"/>
      </geometry>
      <material name="black"/>
    </visual>
    <collision>
      <origin rpy="0 0 0" xyz="0 0 0.0225"/>
      <geometry>
        <cylinder length="0.045" radius="0.05"/>
      </geometry>
    </collision>
  </link>
  <joint name="right_front_wheel_joint" type="continuous">
    <origin rpy="1.5708 0 0" xyz="0 0 0"/>
    <parent link="right_steering_hinge"/>
    <child link="right_front_wheel"/>
    <axis xyz="0 0 -1"/>
    <limit effort="10" velocity="100"/>
  </joint>
  <transmission name="right_front_wheel_transmission" type="SimpleTransmission">
    <type>transmission_interface/SimpleTransmission</type>
    <joint name="right_front_wheel_joint">
      <hardwareInterface>EffortJointInterface</hardwareInterface>
    </joint>
    <actuator name="right_front_wheel_motor">
      <hardwareInterface>EffortJointInterface</hardwareInterface>
      <mechanicalReduction>1</mechanicalReduction>
    </actuator>
  </transmission>


  <!-- Add Openni Kinect camera -->
  <link name="camera_link">
   <visual name="visual">
	<origin xyz="0.3 0 -0.4225" rpy="0 0 0"/>
        <geometry>
          <mesh filename="package://car_description/meshes/kinect.dae" />
        </geometry>
      </visual>
    <inertial>
      <mass value="1e-5"/>
      <origin rpy="0 0 0" xyz="0 0 0"/>
      <inertia ixx="1e-6" ixy="0" ixz="0" iyy="1e-6" iyz="0" izz="1e-6"/>
    </inertial>
  </link>

  <joint name="camera_joint" type="fixed">
    <parent link="chassis"/>
    <child link="camera_link"/>
    <origin xyz="0 0 0.5" rpy="0 0 0"/>
  </joint>
  <link name="camera_link_optical">
    <inertial>
      <mass value="1"/>
      <inertia ixx="0.001" ixy="0.0" ixz="0.0" iyy="0.001" iyz="0.0" izz="0.001"/>
    </inertial>
  </link>
  <joint name="camera_optical_joint" type="fixed">
    <origin xyz="0 0 0" rpy="-1.5707 0 -1.5707"/>
    <parent link="camera_link"/>
    <child link="camera_link_optical"/>
  </joint>

 <joint name="camera_depth_joint" type="fixed">
        <origin xyz="0.0 -0.02 0.0" rpy="0 0 0" />
        <parent link="camera_link" />
        <child link="camera_depth_frame"/>
      </joint>

      <link name="camera_depth_frame"/>

      <joint name="camera_depth_optical_joint" type="fixed">
        <origin xyz="0 0 0" rpy="-1.5707 0.0 -1.5707" />
        <parent link="camera_depth_frame" />
        <child link="camera_depth_optical_frame"/>
      </joint>

      <link name="camera_depth_optical_frame"/>

  <!-- Add the remaining xacros -->
  <!-- Gazebo references -->
  <gazebo reference="chassis">
    <mu1 value="0.0"/>
    <mu2 value="0.0"/>
    <kp value="10000000.0"/>
    <kd value="1.0"/>
    <material>Gazebo/Blue</material>
  </gazebo>
  <gazebo reference="left_rear_wheel">
    <mu1 value="1.0"/>
    <mu2 value="1.0"/>
    <kp value="10000000.0"/>
    <kd value="1.0"/>
    <fdir1 value="1 0 0"/>
    <material>Gazebo/Black</material>
  </gazebo>
  <gazebo reference="right_rear_wheel">
    <mu1 value="1.0"/>
    <mu2 value="1.0"/>
    <kp value="10000000.0"/>
    <kd value="1.0"/>
    <fdir1 value="1 0 0"/>
    <material>Gazebo/Black</material>
  </gazebo>
  <gazebo reference="left_front_wheel">
    <mu1 value="1.0"/>
    <mu2 value="1.0"/>
    <kp value="10000000.0"/>
    <kd value="1.0"/>
    <fdir1 value="0 0 1"/>
    <material>Gazebo/Black</material>
  </gazebo>
  <gazebo reference="right_front_wheel">
    <mu1 value="1.0"/>
    <mu2 value="1.0"/>
    <kp value="10000000.0"/>
    <kd value="1.0"/>
    <fdir1 value="0 0 1"/>
    <material>Gazebo/Black</material>
  </gazebo>
  <!-- Gazebo plugins -->
  <gazebo>
    <plugin filename="libgazebo_ros_control.so" name="gazebo_ros_control">
      <robotNamespace>/car</robotNamespace>
      <robotSimType>gazebo_ros_control/DefaultRobotHWSim</robotSimType>
      <legacyModeNS>true</legacyModeNS>
    </plugin>
  </gazebo>


<!-- Openni Kinect Camera -->

<gazebo reference="camera_link">
  <sensor name="camera_link_camera" type="depth">
    <visualize>true</visualize>             
    <update_rate>10.0</update_rate>
    <camera>
      <horizontal_fov>1.047198</horizontal_fov>
      <image>
        <width>640</width>
        <height>480</height>
        <format>R8G8B8</format>
      </image>
      <depth_camera>
	
      </depth_camera>
      <clip>
        <near>0.45</near>
        <far>5</far>
      </clip>
    </camera>
      <plugin name="camera_controller" filename="libgazebo_ros_openni_kinect.so">
      <baseline>0.2</baseline>
      <alwaysOn>true</alwaysOn>
      <updateRate>0.0</updateRate>
      <imageTopicName>/camera/rgb/image_raw</imageTopicName>
      <depthImageTopicName>/camera/depth/image_raw</depthImageTopicName>
      <pointCloudTopicName>/camera/depth/points</pointCloudTopicName>
      <cameraInfoTopicName>/camera/rgb/camera_info</cameraInfoTopicName>
      <depthImageCameraInfoTopicName>/camera/depth/camera_info</depthImageCameraInfoTopicName>
      <frameName>camera_depth_optical_frame</frameName>
      <pointCloudCutoff>0.45</pointCloudCutoff>
      <hackBaseline>0.07</hackBaseline>
      <distortionK1>0.0</distortionK1>
      <distortionK2>0.0</distortionK2>
      <distortionK3>0.0</distortionK3>
      <distortionT1>0.0</distortionT1>
      <distortionT2>0.0</distortionT2>
      <CxPrime>0</CxPrime>
      <Cx>0</Cx>
      <Cy>0</Cy>
      <focalLength>0</focalLength>
    </plugin>
  </sensor>
</gazebo>

  <material name="black">
    <color rgba="0.0 0.0 0.0 1.0"/>
  </material>
  <material name="blue">
    <color rgba="0.0 0.0 0.8 1.0"/>
  </material>
  <material name="green">
    <color rgba="0.0 0.8 0.0 1.0"/>
  </material>
  <material name="grey">
    <color rgba="0.2 0.2 0.2 1.0"/>
  </material>
  <material name="orange">
    <color rgba="1.0 0.423529411765 0.0392156862745 1.0"/>
  </material>
  <material name="brown">
    <color rgba="0.870588235294 0.811764705882 0.764705882353 1.0"/>
  </material>
  <material name="red">
    <color rgba="0.8 0.0 0.0 1.0"/>
  </material>
  <material name="white">
    <color rgba="1.0 1.0 1.0 1.0"/>
  </material>
</robot>

